Traceback (most recent call last):
  File "dataframe.py", line 4, in <module>
    df = pd.read_csv("\\10.79.27.72\第四nw担当\999_個人フォルダ\江藤\python\data.csv", delimiter=",")
  File "C:\Users\2664810\AppData\Roaming\Python\Python37\site-packages\pandas\io\parsers.py", line 685, in parser_f
    return _read(filepath_or_buffer, kwds)
  File "C:\Users\2664810\AppData\Roaming\Python\Python37\site-packages\pandas\io\parsers.py", line 457, in _read
    parser = TextFileReader(fp_or_buf, **kwds)
  File "C:\Users\2664810\AppData\Roaming\Python\Python37\site-packages\pandas\io\parsers.py", line 895, in __init__
    self._make_engine(self.engine)
  File "C:\Users\2664810\AppData\Roaming\Python\Python37\site-packages\pandas\io\parsers.py", line 1135, in _make_engine
    self._engine = CParserWrapper(self.f, **self.options)
  File "C:\Users\2664810\AppData\Roaming\Python\Python37\site-packages\pandas\io\parsers.py", line 1917, in __init__
    self._reader = parsers.TextReader(src, **kwds)
  File "pandas/_libs/parsers.pyx", line 382, in pandas._libs.parsers.TextReader.__cinit__
  File "pandas/_libs/parsers.pyx", line 689, in pandas._libs.parsers.TextReader._setup_parser_source
FileNotFoundError: [Errno 2] File b'\\10.79.27.72\\\xe7\xac\xac\xe5\x9b\x9bnw\xe6\x8b\x85\xe5\xbd\x93\\999_\xe5\x80\x8b\xe4\xba\xba\xe3\x83\x95\xe3\x82\xa9\xe3\x83\xab\xe3\x83\x80\\\xe6\xb1\x9f\xe8\x97\xa4\\python\\data.csv' does not exist: b'\\10.79.27.72\\\xe7\xac\xac\xe5\x9b\x9bnw\xe6\x8b\x85\xe5\xbd\x93\\999_\xe5\x80\x8b\xe4\xba\xba\xe3\x83\x95\xe3\x82\xa9\xe3\x83\xab\xe3\x83\x80\\\xe6\xb1\x9f\xe8\x97\xa4\\python\\data.csv'

C:\Users\2664810\Desktop\python>python dataframe.py
Traceback (most recent call last):
  File "dataframe.py", line 4, in <module>
    df = pd.read_csv("\\10.79.27.72\第四nw担当\999_個人フォルダ\江藤\python\data.csv")
  File "C:\Users\2664810\AppData\Roaming\Python\Python37\site-packages\pandas\io\parsers.py", line 685, in parser_f
    return _read(filepath_or_buffer, kwds)
  File "C:\Users\2664810\AppData\Roaming\Python\Python37\site-packages\pandas\io\parsers.py", line 457, in _read
    parser = TextFileReader(fp_or_buf, **kwds)
  File "C:\Users\2664810\AppData\Roaming\Python\Python37\site-packages\pandas\io\parsers.py", line 895, in __init__
    self._make_engine(self.engine)
  File "C:\Users\2664810\AppData\Roaming\Python\Python37\site-packages\pandas\io\parsers.py", line 1135, in _make_engine
    self._engine = CParserWrapper(self.f, **self.options)
  File "C:\Users\2664810\AppData\Roaming\Python\Python37\site-packages\pandas\io\parsers.py", line 1917, in __init__
    self._reader = parsers.TextReader(src, **kwds)
  File "pandas/_libs/parsers.pyx", line 382, in pandas._libs.parsers.TextReader.__cinit__
  File "pandas/_libs/parsers.pyx", line 689, in pandas._libs.parsers.TextReader._setup_parser_source
FileNotFoundError: [Errno 2] File b'\\10.79.27.72\\\xe7\xac\xac\xe5\x9b\x9bnw\xe6\x8b\x85\xe5\xbd\x93\\999_\xe5\x80\x8b\xe4\xba\xba\xe3\x83\x95\xe3\x82\xa9\xe3\x83\xab\xe3\x83\x80\\\xe6\xb1\x9f\xe8\x97\xa4\\python\\data.csv' does not exist: b'\\10.79.27.72\\\xe7\xac\xac\xe5\x9b\x9bnw\xe6\x8b\x85\xe5\xbd\x93\\999_\xe5\x80\x8b\xe4\xba\xba\xe3\x83\x95\xe3\x82\xa9\xe3\x83\xab\xe3\x83\x80\\\xe6\xb1\x9f\xe8\x97\xa4\\python\\data.csv'

C:\Users\2664810\Desktop\python>python dataframe.py
Traceback (most recent call last):
  File "dataframe.py", line 4, in <module>
    df = pd.read_csv("\\10.79.27.72\第四nw担当\999_個人フォルダ\江藤\python\data.csv",encoding="SHIFT-JIS")
  File "C:\Users\2664810\AppData\Roaming\Python\Python37\site-packages\pandas\io\parsers.py", line 685, in parser_f
    return _read(filepath_or_buffer, kwds)
  File "C:\Users\2664810\AppData\Roaming\Python\Python37\site-packages\pandas\io\parsers.py", line 457, in _read
    parser = TextFileReader(fp_or_buf, **kwds)
  File "C:\Users\2664810\AppData\Roaming\Python\Python37\site-packages\pandas\io\parsers.py", line 895, in __init__
    self._make_engine(self.engine)
  File "C:\Users\2664810\AppData\Roaming\Python\Python37\site-packages\pandas\io\parsers.py", line 1135, in _make_engine
    self._engine = CParserWrapper(self.f, **self.options)
  File "C:\Users\2664810\AppData\Roaming\Python\Python37\site-packages\pandas\io\parsers.py", line 1917, in __init__
    self._reader = parsers.TextReader(src, **kwds)
  File "pandas/_libs/parsers.pyx", line 382, in pandas._libs.parsers.TextReader.__cinit__
  File "pandas/_libs/parsers.pyx", line 689, in pandas._libs.parsers.TextReader._setup_parser_source
FileNotFoundError: [Errno 2] File b'\\10.79.27.72\\\xe7\xac\xac\xe5\x9b\x9bnw\xe6\x8b\x85\xe5\xbd\x93\\999_\xe5\x80\x8b\xe4\xba\xba\xe3\x83\x95\xe3\x82\xa9\xe3\x83\xab\xe3\x83\x80\\\xe6\xb1\x9f\xe8\x97\xa4\\python\\data.csv' does not exist: b'\\10.79.27.72\\\xe7\xac\xac\xe5\x9b\x9bnw\xe6\x8b\x85\xe5\xbd\x93\\999_\xe5\x80\x8b\xe4\xba\xba\xe3\x83\x95\xe3\x82\xa9\xe3\x83\xab\xe3\x83\x80\\\xe6\xb1\x9f\xe8\x97\xa4\\python\\data.csv'

C:\Users\2664810\Desktop\python>python dataframe.py
  File "dataframe.py", line 5
    os.chdir("\\10.79.27.72\第四nw担当\999_個人フォルダ\江藤\python\")
                                                          ^
SyntaxError: EOL while scanning string literal

C:\Users\2664810\Desktop\python>python dataframe.py
Traceback (most recent call last):
  File "dataframe.py", line 5, in <module>
    os.chdir("\\10.79.27.72\第四nw担当\999_個人フォルダ\江藤\python")
FileNotFoundError: [WinError 3] 指定されたパスが見つかりません。: '\\10.79.27.72\\第四nw担当\\999_個人フォルダ\\江藤\\python'

C:\Users\2664810\Desktop\python>python dataframe.py
Traceback (most recent call last):
  File "dataframe.py", line 5, in <module>
    os.chdir("\\10.79.27.72\第四nw担当\999_個人フォルダ\江藤\python")
FileNotFoundError: [WinError 3] 指定されたパスが見つかりません。: '\\10.79.27.72\\第四nw担当\\999_個人フォルダ\\江藤\\python'

C:\Users\2664810\Desktop\python>python dataframe.py
Traceback (most recent call last):
  File "dataframe.py", line 6, in <module>
    df = pd.read_csv(path,delimiter=",")
  File "C:\Users\2664810\AppData\Roaming\Python\Python37\site-packages\pandas\io\parsers.py", line 685, in parser_f
    return _read(filepath_or_buffer, kwds)
  File "C:\Users\2664810\AppData\Roaming\Python\Python37\site-packages\pandas\io\parsers.py", line 457, in _read
    parser = TextFileReader(fp_or_buf, **kwds)
  File "C:\Users\2664810\AppData\Roaming\Python\Python37\site-packages\pandas\io\parsers.py", line 895, in __init__
    self._make_engine(self.engine)
  File "C:\Users\2664810\AppData\Roaming\Python\Python37\site-packages\pandas\io\parsers.py", line 1135, in _make_engine
    self._engine = CParserWrapper(self.f, **self.options)
  File "C:\Users\2664810\AppData\Roaming\Python\Python37\site-packages\pandas\io\parsers.py", line 1917, in __init__
    self._reader = parsers.TextReader(src, **kwds)
  File "pandas/_libs/parsers.pyx", line 382, in pandas._libs.parsers.TextReader.__cinit__
  File "pandas/_libs/parsers.pyx", line 689, in pandas._libs.parsers.TextReader._setup_parser_source
FileNotFoundError: [Errno 2] File b'\\10.79.27.72\\\xe7\xac\xac\xe5\x9b\x9bnw\xe6\x8b\x85\xe5\xbd\x93\\999_\xe5\x80\x8b\xe4\xba\xba\xe3\x83\x95\xe3\x82\xa9\xe3\x83\xab\xe3\x83\x80\\\xe6\xb1\x9f\xe8\x97\xa4\\python\\data.csv' does not exist: b'\\10.79.27.72\\\xe7\xac\xac\xe5\x9b\x9bnw\xe6\x8b\x85\xe5\xbd\x93\\999_\xe5\x80\x8b\xe4\xba\xba\xe3\x83\x95\xe3\x82\xa9\xe3\x83\xab\xe3\x83\x80\\\xe6\xb1\x9f\xe8\x97\xa4\\python\\data.csv'

C:\Users\2664810\Desktop\python>python dataframe.py
Traceback (most recent call last):
  File "dataframe.py", line 6, in <module>
    df = pd.read_csv(r"\\10.79.27.72\第四nw担当\999_個人フォルダ\江藤\python\data.csv",delimiter=",")
  File "C:\Users\2664810\AppData\Roaming\Python\Python37\site-packages\pandas\io\parsers.py", line 685, in parser_f
    return _read(filepath_or_buffer, kwds)
  File "C:\Users\2664810\AppData\Roaming\Python\Python37\site-packages\pandas\io\parsers.py", line 457, in _read
    parser = TextFileReader(fp_or_buf, **kwds)
  File "C:\Users\2664810\AppData\Roaming\Python\Python37\site-packages\pandas\io\parsers.py", line 895, in __init__
    self._make_engine(self.engine)
  File "C:\Users\2664810\AppData\Roaming\Python\Python37\site-packages\pandas\io\parsers.py", line 1135, in _make_engine
    self._engine = CParserWrapper(self.f, **self.options)
  File "C:\Users\2664810\AppData\Roaming\Python\Python37\site-packages\pandas\io\parsers.py", line 1917, in __init__
    self._reader = parsers.TextReader(src, **kwds)
  File "pandas/_libs/parsers.pyx", line 542, in pandas._libs.parsers.TextReader.__cinit__
  File "pandas/_libs/parsers.pyx", line 764, in pandas._libs.parsers.TextReader._get_header
UnicodeDecodeError: 'utf-8' codec can't decode byte 0x96 in position 0: invalid start byte

C:\Users\2664810\Desktop\python>python dataframe.py
Traceback (most recent call last):
  File "dataframe.py", line 6, in <module>
    df = pd.read_csv(r"\\10.79.27.72\第四nw担当\999_個人フォルダ\江藤\python\data.csv")
  File "C:\Users\2664810\AppData\Roaming\Python\Python37\site-packages\pandas\io\parsers.py", line 685, in parser_f
    return _read(filepath_or_buffer, kwds)
  File "C:\Users\2664810\AppData\Roaming\Python\Python37\site-packages\pandas\io\parsers.py", line 457, in _read
    parser = TextFileReader(fp_or_buf, **kwds)
  File "C:\Users\2664810\AppData\Roaming\Python\Python37\site-packages\pandas\io\parsers.py", line 895, in __init__
    self._make_engine(self.engine)
  File "C:\Users\2664810\AppData\Roaming\Python\Python37\site-packages\pandas\io\parsers.py", line 1135, in _make_engine
    self._engine = CParserWrapper(self.f, **self.options)
  File "C:\Users\2664810\AppData\Roaming\Python\Python37\site-packages\pandas\io\parsers.py", line 1917, in __init__
    self._reader = parsers.TextReader(src, **kwds)
  File "pandas/_libs/parsers.pyx", line 542, in pandas._libs.parsers.TextReader.__cinit__
  File "pandas/_libs/parsers.pyx", line 764, in pandas._libs.parsers.TextReader._get_header
UnicodeDecodeError: 'utf-8' codec can't decode byte 0x96 in position 0: invalid start byte

C:\Users\2664810\Desktop\python>python dataframe.py
Traceback (most recent call last):
  File "dataframe.py", line 6, in <module>
    df = pd.read_csv(path + "data.csv",delimiter=",")
  File "C:\Users\2664810\AppData\Roaming\Python\Python37\site-packages\pandas\io\parsers.py", line 685, in parser_f
    return _read(filepath_or_buffer, kwds)
  File "C:\Users\2664810\AppData\Roaming\Python\Python37\site-packages\pandas\io\parsers.py", line 457, in _read
    parser = TextFileReader(fp_or_buf, **kwds)
  File "C:\Users\2664810\AppData\Roaming\Python\Python37\site-packages\pandas\io\parsers.py", line 895, in __init__
    self._make_engine(self.engine)
  File "C:\Users\2664810\AppData\Roaming\Python\Python37\site-packages\pandas\io\parsers.py", line 1135, in _make_engine
    self._engine = CParserWrapper(self.f, **self.options)
  File "C:\Users\2664810\AppData\Roaming\Python\Python37\site-packages\pandas\io\parsers.py", line 1917, in __init__
    self._reader = parsers.TextReader(src, **kwds)
  File "pandas/_libs/parsers.pyx", line 382, in pandas._libs.parsers.TextReader.__cinit__
  File "pandas/_libs/parsers.pyx", line 689, in pandas._libs.parsers.TextReader._setup_parser_source
FileNotFoundError: [Errno 2] File b'\\10.79.27.72\\\xe7\xac\xac\xe5\x9b\x9bnw\xe6\x8b\x85\xe5\xbd\x93\\999_\xe5\x80\x8b\xe4\xba\xba\xe3\x83\x95\xe3\x82\xa9\xe3\x83\xab\xe3\x83\x80\\\xe6\xb1\x9f\xe8\x97\xa4\\pythonsdata.csv' does not exist: b'\\10.79.27.72\\\xe7\xac\xac\xe5\x9b\x9bnw\xe6\x8b\x85\xe5\xbd\x93\\999_\xe5\x80\x8b\xe4\xba\xba\xe3\x83\x95\xe3\x82\xa9\xe3\x83\xab\xe3\x83\x80\\\xe6\xb1\x9f\xe8\x97\xa4\\pythonsdata.csv'

C:\Users\2664810\Desktop\python>python dataframe.py
Traceback (most recent call last):
  File "dataframe.py", line 6, in <module>
    df = pd.read_csv(path + "data.csv",delimiter=",")
  File "C:\Users\2664810\AppData\Roaming\Python\Python37\site-packages\pandas\io\parsers.py", line 685, in parser_f
    return _read(filepath_or_buffer, kwds)
  File "C:\Users\2664810\AppData\Roaming\Python\Python37\site-packages\pandas\io\parsers.py", line 457, in _read
    parser = TextFileReader(fp_or_buf, **kwds)
  File "C:\Users\2664810\AppData\Roaming\Python\Python37\site-packages\pandas\io\parsers.py", line 895, in __init__
    self._make_engine(self.engine)
  File "C:\Users\2664810\AppData\Roaming\Python\Python37\site-packages\pandas\io\parsers.py", line 1135, in _make_engine
    self._engine = CParserWrapper(self.f, **self.options)
  File "C:\Users\2664810\AppData\Roaming\Python\Python37\site-packages\pandas\io\parsers.py", line 1917, in __init__
    self._reader = parsers.TextReader(src, **kwds)
  File "pandas/_libs/parsers.pyx", line 382, in pandas._libs.parsers.TextReader.__cinit__
  File "pandas/_libs/parsers.pyx", line 689, in pandas._libs.parsers.TextReader._setup_parser_source
FileNotFoundError: [Errno 2] File b'\\10.79.27.72\\\xe7\xac\xac\xe5\x9b\x9bnw\xe6\x8b\x85\xe5\xbd\x93\\999_\xe5\x80\x8b\xe4\xba\xba\xe3\x83\x95\xe3\x82\xa9\xe3\x83\xab\xe3\x83\x80\\\xe6\xb1\x9f\xe8\x97\xa4\\pythondata.csv' does not exist: b'\\10.79.27.72\\\xe7\xac\xac\xe5\x9b\x9bnw\xe6\x8b\x85\xe5\xbd\x93\\999_\xe5\x80\x8b\xe4\xba\xba\xe3\x83\x95\xe3\x82\xa9\xe3\x83\xab\xe3\x83\x80\\\xe6\xb1\x9f\xe8\x97\xa4\\pythondata.csv'

C:\Users\2664810\Desktop\python>python dataframe.py
Traceback (most recent call last):
  File "dataframe.py", line 6, in <module>
    df = pd.read_csv("\\10.79.27.72\第四nw担当\999_個人フォルダ\江藤\python\data.csv",delimiter=",")
  File "C:\Users\2664810\AppData\Roaming\Python\Python37\site-packages\pandas\io\parsers.py", line 685, in parser_f
    return _read(filepath_or_buffer, kwds)
  File "C:\Users\2664810\AppData\Roaming\Python\Python37\site-packages\pandas\io\parsers.py", line 457, in _read
    parser = TextFileReader(fp_or_buf, **kwds)
  File "C:\Users\2664810\AppData\Roaming\Python\Python37\site-packages\pandas\io\parsers.py", line 895, in __init__
    self._make_engine(self.engine)
  File "C:\Users\2664810\AppData\Roaming\Python\Python37\site-packages\pandas\io\parsers.py", line 1135, in _make_engine
    self._engine = CParserWrapper(self.f, **self.options)
  File "C:\Users\2664810\AppData\Roaming\Python\Python37\site-packages\pandas\io\parsers.py", line 1917, in __init__
    self._reader = parsers.TextReader(src, **kwds)
  File "pandas/_libs/parsers.pyx", line 382, in pandas._libs.parsers.TextReader.__cinit__
  File "pandas/_libs/parsers.pyx", line 689, in pandas._libs.parsers.TextReader._setup_parser_source
FileNotFoundError: [Errno 2] File b'\\10.79.27.72\\\xe7\xac\xac\xe5\x9b\x9bnw\xe6\x8b\x85\xe5\xbd\x93\\999_\xe5\x80\x8b\xe4\xba\xba\xe3\x83\x95\xe3\x82\xa9\xe3\x83\xab\xe3\x83\x80\\\xe6\xb1\x9f\xe8\x97\xa4\\python\\data.csv' does not exist: b'\\10.79.27.72\\\xe7\xac\xac\xe5\x9b\x9bnw\xe6\x8b\x85\xe5\xbd\x93\\999_\xe5\x80\x8b\xe4\xba\xba\xe3\x83\x95\xe3\x82\xa9\xe3\x83\xab\xe3\x83\x80\\\xe6\xb1\x9f\xe8\x97\xa4\\python\\data.csv'


↓code


import pandas as pd
import csv
import os

#path="\\10.79.27.72\第四nw担当\999_個人フォルダ\江藤\python"
df = pd.read_csv("\\10.79.27.72\第四nw担当\999_個人フォルダ\江藤\python\data.csv",delimiter=",")
print(df)
